<?xml version="1.0" ?>
<!-- =================================================================================== -->
<!-- |    This document was autogenerated by xacro from urdf/arm_test_main.xacro       | -->
<!-- |    EDITING THIS FILE BY HAND IS NOT RECOMMENDED                                 | -->
<!-- =================================================================================== -->
<robot name="arm_test_main">
  <material name="silver_default">
    <color rgba="0.700 0.700 0.700 1.000"/>
  </material>
  <material name="steel_satin">
    <color rgba="0.6274509803921569 0.6274509803921569 0.6274509803921569 1.0"/>
  </material>
  <transmission name="Revolute 1_tran">
    <type>transmission_interface/SimpleTransmission</type>
    <joint name="Revolute 1">
      <hardwareInterface>hardware_interface/EffortJointInterface</hardwareInterface>
    </joint>
    <actuator name="Revolute 1_actr">
      <hardwareInterface>hardware_interface/EffortJointInterface</hardwareInterface>
      <mechanicalReduction>1</mechanicalReduction>
    </actuator>
  </transmission>
  <transmission name="Revolute 6_tran">
    <type>transmission_interface/SimpleTransmission</type>
    <joint name="Revolute 6">
      <hardwareInterface>hardware_interface/EffortJointInterface</hardwareInterface>
    </joint>
    <actuator name="Revolute 6_actr">
      <hardwareInterface>hardware_interface/EffortJointInterface</hardwareInterface>
      <mechanicalReduction>1</mechanicalReduction>
    </actuator>
  </transmission>
  <transmission name="Revolute 2_tran">
    <type>transmission_interface/SimpleTransmission</type>
    <joint name="Revolute 2">
      <hardwareInterface>hardware_interface/EffortJointInterface</hardwareInterface>
    </joint>
    <actuator name="Revolute 2_actr">
      <hardwareInterface>hardware_interface/EffortJointInterface</hardwareInterface>
      <mechanicalReduction>1</mechanicalReduction>
    </actuator>
  </transmission>
  <transmission name="Revolute 3_tran">
    <type>transmission_interface/SimpleTransmission</type>
    <joint name="Revolute 3">
      <hardwareInterface>hardware_interface/EffortJointInterface</hardwareInterface>
    </joint>
    <actuator name="Revolute 3_actr">
      <hardwareInterface>hardware_interface/EffortJointInterface</hardwareInterface>
      <mechanicalReduction>1</mechanicalReduction>
    </actuator>
  </transmission>
  <transmission name="Revolute 4_tran">
    <type>transmission_interface/SimpleTransmission</type>
    <joint name="Revolute 4">
      <hardwareInterface>hardware_interface/EffortJointInterface</hardwareInterface>
    </joint>
    <actuator name="Revolute 4_actr">
      <hardwareInterface>hardware_interface/EffortJointInterface</hardwareInterface>
      <mechanicalReduction>1</mechanicalReduction>
    </actuator>
  </transmission>
  <transmission name="Revolute 5_tran">
    <type>transmission_interface/SimpleTransmission</type>
    <joint name="Revolute 5">
      <hardwareInterface>hardware_interface/EffortJointInterface</hardwareInterface>
    </joint>
    <actuator name="Revolute 5_actr">
      <hardwareInterface>hardware_interface/EffortJointInterface</hardwareInterface>
      <mechanicalReduction>1</mechanicalReduction>
    </actuator>
  </transmission>
  <link name="base_link">
    <inertial>
      <origin rpy="0 0 0" xyz="0.0003499999845567354 -0.055451634605518364 -0.01655773729685415"/>
      <mass value="0.3893898243402566"/>
      <inertia ixx="0.000131" ixy="-0.0" ixz="-0.0" iyy="7.1e-05" iyz="-2e-06" izz="0.000111"/>
    </inertial>
    <visual>
      <origin rpy="0 0 0" xyz="0 0 0"/>
      <geometry>
        <mesh filename="../meshes/base_link.stl" scale="0.001 0.001 0.001"/>
      </geometry>
      <material name="steel_satin"/>
    </visual>
    <collision>
      <origin rpy="0 0 0" xyz="0 0 0"/>
      <geometry>
        <mesh filename="../meshes/base_link.stl" scale="0.001 0.001 0.001"/>
      </geometry>
    </collision>
  </link>
  <link name="pitch_1_test_v5_1">
    <inertial>
      <origin rpy="0 0 0" xyz="-0.0002232261084468942 0.037799318734209816 -0.0010892901314620007"/>
      <mass value="0.5173712582672985"/>
      <inertia ixx="0.000268" ixy="2e-06" ixz="1e-06" iyy="0.000174" iyz="-6.3e-05" izz="0.000212"/>
    </inertial>
    <visual>
      <origin rpy="0 0 0" xyz="-0.00035 0.0369 -0.0062"/>
      <geometry>
        <mesh filename="../meshes/pitch_1_test_v5_1.stl" scale="0.001 0.001 0.001"/>
      </geometry>
      <material name="steel_satin"/>
    </visual>
    <collision>
      <origin rpy="0 0 0" xyz="-0.00035 0.0369 -0.0062"/>
      <geometry>
        <mesh filename="../meshes/pitch_1_test_v5_1.stl" scale="0.001 0.001 0.001"/>
      </geometry>
    </collision>
  </link>
  <link name="hand_finger_v1_1">
    <inertial>
      <origin rpy="0 0 0" xyz="-0.02170000000000309 0.036124214048086134 0.024494705961264657"/>
      <mass value="0.18407843738656002"/>
      <inertia ixx="0.000116" ixy="0.0" ixz="0.0" iyy="5e-05" iyz="-2.8e-05" izz="0.000135"/>
    </inertial>
    <visual>
      <origin rpy="0 0 0" xyz="-0.0215 -0.20995 -0.02465"/>
      <geometry>
        <mesh filename="../meshes/hand_finger_v1_1.stl" scale="0.001 0.001 0.001"/>
      </geometry>
      <material name="steel_satin"/>
    </visual>
    <collision>
      <origin rpy="0 0 0" xyz="-0.0215 -0.20995 -0.02465"/>
      <geometry>
        <mesh filename="../meshes/hand_finger_v1_1.stl" scale="0.001 0.001 0.001"/>
      </geometry>
    </collision>
  </link>
  <link name="roll_1_test_v11_1">
    <inertial>
      <origin rpy="0 0 0" xyz="-0.02120000001136538 0.03553001060803644 0.017590075270092268"/>
      <mass value="0.45569427768407117"/>
      <inertia ixx="0.000164" ixy="-0.0" ixz="0.0" iyy="0.00015" iyz="-1.1e-05" izz="0.00013"/>
    </inertial>
    <visual>
      <origin rpy="0 0 0" xyz="-0.0207 -0.0253 -0.01165"/>
      <geometry>
        <mesh filename="../meshes/roll_1_test_v11_1.stl" scale="0.001 0.001 0.001"/>
      </geometry>
      <material name="steel_satin"/>
    </visual>
    <collision>
      <origin rpy="0 0 0" xyz="-0.0207 -0.0253 -0.01165"/>
      <geometry>
        <mesh filename="../meshes/roll_1_test_v11_1.stl" scale="0.001 0.001 0.001"/>
      </geometry>
    </collision>
  </link>
  <link name="pitch_2_test_v1_1">
    <inertial>
      <origin rpy="0 0 0" xyz="0.0003543930189758741 0.026889206855970238 -2.973126154992567e-10"/>
      <mass value="0.4049688490988578"/>
      <inertia ixx="0.000118" ixy="2e-06" ixz="0.0" iyy="7.6e-05" iyz="-0.0" izz="0.000143"/>
    </inertial>
    <visual>
      <origin rpy="0 0 0" xyz="0.0005 -0.0817 -0.01165"/>
      <geometry>
        <mesh filename="../meshes/pitch_2_test_v1_1.stl" scale="0.001 0.001 0.001"/>
      </geometry>
      <material name="steel_satin"/>
    </visual>
    <collision>
      <origin rpy="0 0 0" xyz="0.0005 -0.0817 -0.01165"/>
      <geometry>
        <mesh filename="../meshes/pitch_2_test_v1_1.stl" scale="0.001 0.001 0.001"/>
      </geometry>
    </collision>
  </link>
  <link name="roll_2_test_v1_1">
    <inertial>
      <origin rpy="0 0 0" xyz="-0.021200000011342975 0.03553313851539064 0.01761719047417286"/>
      <mass value="0.45660397486942944"/>
      <inertia ixx="0.000165" ixy="-0.0" ixz="0.0" iyy="0.000151" iyz="-1.1e-05" izz="0.00013"/>
    </inertial>
    <visual>
      <origin rpy="0 0 0" xyz="-0.0205 -0.1279 -0.01165"/>
      <geometry>
        <mesh filename="../meshes/roll_2_test_v1_1.stl" scale="0.001 0.001 0.001"/>
      </geometry>
      <material name="steel_satin"/>
    </visual>
    <collision>
      <origin rpy="0 0 0" xyz="-0.0205 -0.1279 -0.01165"/>
      <geometry>
        <mesh filename="../meshes/roll_2_test_v1_1.stl" scale="0.001 0.001 0.001"/>
      </geometry>
    </collision>
  </link>
  <link name="hand_unit_v1_1">
    <inertial>
      <origin rpy="0 0 0" xyz="-0.00015861142460390045 0.032553601595988524 -0.014188170173816673"/>
      <mass value="0.6163609537224307"/>
      <inertia ixx="0.000491" ixy="1e-06" ixz="-3e-06" iyy="0.000278" iyz="0.000125" izz="0.000371"/>
    </inertial>
    <visual>
      <origin rpy="0 0 0" xyz="0.0007 -0.1843 -0.01165"/>
      <geometry>
        <mesh filename="../meshes/hand_unit_v1_1.stl" scale="0.001 0.001 0.001"/>
      </geometry>
      <material name="steel_satin"/>
    </visual>
    <collision>
      <origin rpy="0 0 0" xyz="0.0007 -0.1843 -0.01165"/>
      <geometry>
        <mesh filename="../meshes/hand_unit_v1_1.stl" scale="0.001 0.001 0.001"/>
      </geometry>
    </collision>
  </link>
  <joint name="Revolute 1" type="revolute">
    <origin rpy="0 0 0" xyz="0.00035 -0.0369 0.0062"/>
    <parent link="base_link"/>
    <child link="pitch_1_test_v5_1"/>
    <axis xyz="0.0 0.0 -1.0"/>
    <limit effort="100" lower="-1.570796" upper="1.570796" velocity="100"/>
  </joint>
  <joint name="Revolute 6" type="revolute">
    <origin rpy="0 0 0" xyz="0.0222 0.02565 0.013"/>
    <parent link="hand_unit_v1_1"/>
    <child link="hand_finger_v1_1"/>
    <axis xyz="-1.0 -0.0 0.0"/>
    <limit effort="100" lower="-1.047198" upper="0.872665" velocity="100"/>
  </joint>
  <joint name="Revolute 2" type="revolute">
    <origin rpy="0 0 0" xyz="0.02035 0.0622 0.00545"/>
    <parent link="pitch_1_test_v5_1"/>
    <child link="roll_1_test_v11_1"/>
    <axis xyz="-1.0 -0.0 -0.0"/>
    <limit effort="100" lower="-1.396263" upper="1.745329" velocity="100"/>
  </joint>
  <joint name="Revolute 3" type="continuous">
    <origin rpy="0 0 0" xyz="-0.0212 0.0564 0.0"/>
    <parent link="roll_1_test_v11_1"/>
    <child link="pitch_2_test_v1_1"/>
    <axis xyz="-0.0 1.0 -0.0"/>
  </joint>
  <joint name="Revolute 4" type="revolute">
    <origin rpy="0 0 0" xyz="0.021 0.0462 0.0"/>
    <parent link="pitch_2_test_v1_1"/>
    <child link="roll_2_test_v1_1"/>
    <axis xyz="-1.0 0.0 -0.0"/>
    <limit effort="100" lower="-1.396263" upper="1.919862" velocity="100"/>
  </joint>
  <joint name="Revolute 5" type="continuous">
    <origin rpy="0 0 0" xyz="-0.0212 0.0564 0.0"/>
    <parent link="roll_2_test_v1_1"/>
    <child link="hand_unit_v1_1"/>
    <axis xyz="0.0 -1.0 -0.0"/>
  </joint>
</robot>
