<?xml version="1.0" ?>
<!-- =================================================================================== -->
<!-- |    This document was autogenerated by xacro from urdf/arm_main.xacro            | -->
<!-- |    EDITING THIS FILE BY HAND IS NOT RECOMMENDED                                 | -->
<!-- =================================================================================== -->
<robot name="arm_main">
  <material name="silver_default">
    <color rgba="0.700 0.700 0.700 1.000"/>
  </material>
  <material name="steel_satin">
    <color rgba="0.6274509803921569 0.6274509803921569 0.6274509803921569 1.0"/>
  </material>
  <transmission name="Revolute 7_tran">
    <type>transmission_interface/SimpleTransmission</type>
    <joint name="Revolute 7">
      <hardwareInterface>hardware_interface/EffortJointInterface</hardwareInterface>
    </joint>
    <actuator name="Revolute 7_actr">
      <hardwareInterface>hardware_interface/EffortJointInterface</hardwareInterface>
      <mechanicalReduction>1</mechanicalReduction>
    </actuator>
  </transmission>
  <transmission name="Revolute 8_tran">
    <type>transmission_interface/SimpleTransmission</type>
    <joint name="Revolute 8">
      <hardwareInterface>hardware_interface/EffortJointInterface</hardwareInterface>
    </joint>
    <actuator name="Revolute 8_actr">
      <hardwareInterface>hardware_interface/EffortJointInterface</hardwareInterface>
      <mechanicalReduction>1</mechanicalReduction>
    </actuator>
  </transmission>
  <transmission name="Revolute 9_tran">
    <type>transmission_interface/SimpleTransmission</type>
    <joint name="Revolute 9">
      <hardwareInterface>hardware_interface/EffortJointInterface</hardwareInterface>
    </joint>
    <actuator name="Revolute 9_actr">
      <hardwareInterface>hardware_interface/EffortJointInterface</hardwareInterface>
      <mechanicalReduction>1</mechanicalReduction>
    </actuator>
  </transmission>
  <transmission name="Revolute 11_tran">
    <type>transmission_interface/SimpleTransmission</type>
    <joint name="Revolute 11">
      <hardwareInterface>hardware_interface/EffortJointInterface</hardwareInterface>
    </joint>
    <actuator name="Revolute 11_actr">
      <hardwareInterface>hardware_interface/EffortJointInterface</hardwareInterface>
      <mechanicalReduction>1</mechanicalReduction>
    </actuator>
  </transmission>
  <link name="base_link">
    <inertial>
      <origin rpy="0 0 0" xyz="-0.0012214089016151053 0.02712127606702909 -0.02444560560426352"/>
      <mass value="0.8833573620888653"/>
      <inertia ixx="0.001118" ixy="3e-06" ixz="-4e-06" iyy="0.000472" iyz="0.000355" izz="0.000805"/>
    </inertial>
    <visual>
      <origin rpy="0 0 0" xyz="0 0 0"/>
      <geometry>
        <mesh filename="../meshes/base_link.stl" scale="0.001 0.001 0.001"/>
      </geometry>
      <material name="steel_satin"/>
    </visual>
    <collision>
      <origin rpy="0 0 0" xyz="0 0 0"/>
      <geometry>
        <mesh filename="../meshes/base_link.stl" scale="0.001 0.001 0.001"/>
      </geometry>
    </collision>
  </link>
  <link name="servo_holder2_v2_1">
    <inertial>
      <origin rpy="0 0 0" xyz="-0.023124515666649855 0.08470253666904037 -8.411334129210246e-12"/>
      <mass value="0.7144775958239902"/>
      <inertia ixx="0.001083" ixy="-2e-06" ixz="0.0" iyy="0.000178" iyz="0.0" izz="0.001183"/>
    </inertial>
    <visual>
      <origin rpy="0 0 0" xyz="-0.0227 -0.1264 -0.04195"/>
      <geometry>
        <mesh filename="../meshes/servo_holder2_v2_1.stl" scale="0.001 0.001 0.001"/>
      </geometry>
      <material name="steel_satin"/>
    </visual>
    <collision>
      <origin rpy="0 0 0" xyz="-0.0227 -0.1264 -0.04195"/>
      <geometry>
        <mesh filename="../meshes/servo_holder2_v2_1.stl" scale="0.001 0.001 0.001"/>
      </geometry>
    </collision>
  </link>
  <link name="hand_rotation_v11_4">
    <inertial>
      <origin rpy="0 0 0" xyz="-0.023199999989499457 0.03605179829238042 -0.019122913280508146"/>
      <mass value="0.5077046555158917"/>
      <inertia ixx="0.000247" ixy="-0.0" ixz="0.0" iyy="0.000181" iyz="7e-06" izz="0.000228"/>
    </inertial>
    <visual>
      <origin rpy="0 0 0" xyz="-0.0227 -0.2576 -0.04195"/>
      <geometry>
        <mesh filename="../meshes/hand_rotation_v11_4.stl" scale="0.001 0.001 0.001"/>
      </geometry>
      <material name="steel_satin"/>
    </visual>
    <collision>
      <origin rpy="0 0 0" xyz="-0.0227 -0.2576 -0.04195"/>
      <geometry>
        <mesh filename="../meshes/hand_rotation_v11_4.stl" scale="0.001 0.001 0.001"/>
      </geometry>
    </collision>
  </link>
  <link name="hand_v15_1">
    <inertial>
      <origin rpy="0 0 0" xyz="0.0018662468545444656 0.046209557945012414 -9.894154345851947e-06"/>
      <mass value="0.8683719536760056"/>
      <inertia ixx="0.000728" ixy="0.000141" ixz="8e-06" iyy="0.000758" iyz="-2e-06" izz="0.001224"/>
    </inertial>
    <visual>
      <origin rpy="0 0 0" xyz="0.0005 -0.318 -0.04195"/>
      <geometry>
        <mesh filename="../meshes/hand_v15_1.stl" scale="0.001 0.001 0.001"/>
      </geometry>
      <material name="steel_satin"/>
    </visual>
    <collision>
      <origin rpy="0 0 0" xyz="0.0005 -0.318 -0.04195"/>
      <geometry>
        <mesh filename="../meshes/hand_v15_1.stl" scale="0.001 0.001 0.001"/>
      </geometry>
    </collision>
  </link>
  <link name="servo_holder_v15_3">
    <inertial>
      <origin rpy="0 0 0" xyz="-0.02326241518713279 0.09672306724863754 0.006744967499623274"/>
      <mass value="0.6761166227960398"/>
      <inertia ixx="0.001236" ixy="1e-06" ixz="1e-06" iyy="0.000249" iyz="-0.000135" izz="0.001269"/>
    </inertial>
    <visual>
      <origin rpy="0 0 0" xyz="-0.0227 -0.0 -0.0125"/>
      <geometry>
        <mesh filename="../meshes/servo_holder_v15_3.stl" scale="0.001 0.001 0.001"/>
      </geometry>
      <material name="steel_satin"/>
    </visual>
    <collision>
      <origin rpy="0 0 0" xyz="-0.0227 -0.0 -0.0125"/>
      <geometry>
        <mesh filename="../meshes/servo_holder_v15_3.stl" scale="0.001 0.001 0.001"/>
      </geometry>
    </collision>
  </link>
  <joint name="Revolute 7" type="continuous">
    <origin rpy="0 0 0" xyz="0.0 0.1264 0.02945"/>
    <parent link="servo_holder_v15_3"/>
    <child link="servo_holder2_v2_1"/>
    <axis xyz="-1.0 0.0 0.0"/>
  </joint>
  <joint name="Revolute 8" type="continuous">
    <origin rpy="0 0 0" xyz="0.0 0.1312 0.0"/>
    <parent link="servo_holder2_v2_1"/>
    <child link="hand_rotation_v11_4"/>
    <axis xyz="1.0 -0.0 -0.0"/>
  </joint>
  <joint name="Revolute 9" type="continuous">
    <origin rpy="0 0 0" xyz="-0.0232 0.0604 0.0"/>
    <parent link="hand_rotation_v11_4"/>
    <child link="hand_v15_1"/>
    <axis xyz="-0.0 -1.0 -0.0"/>
  </joint>
  <joint name="Revolute 11" type="continuous">
    <origin rpy="0 0 0" xyz="0.0227 0.0 0.0125"/>
    <parent link="base_link"/>
    <child link="servo_holder_v15_3"/>
    <axis xyz="-1.0 -0.0 -0.0"/>
  </joint>
</robot>
